2019-05-09 16:00:00,093 : ERROR: Exception on / [GET] [in /home/shashi/libs/anaconda3/lib/python2.7/site-packages/flask/app.py:1761]
Traceback (most recent call last):
  File "/home/shashi/libs/anaconda3/lib/python2.7/site-packages/flask/app.py", line 2292, in wsgi_app
    response = self.full_dispatch_request()
  File "/home/shashi/libs/anaconda3/lib/python2.7/site-packages/flask/app.py", line 1815, in full_dispatch_request
    rv = self.handle_user_exception(e)
  File "/home/shashi/libs/anaconda3/lib/python2.7/site-packages/flask/app.py", line 1718, in handle_user_exception
    reraise(exc_type, exc_value, tb)
  File "/home/shashi/libs/anaconda3/lib/python2.7/site-packages/flask/app.py", line 1813, in full_dispatch_request
    rv = self.dispatch_request()
  File "/home/shashi/libs/anaconda3/lib/python2.7/site-packages/flask/app.py", line 1799, in dispatch_request
    return self.view_functions[rule.endpoint](**req.view_args)
  File "/home/shashi/Desktop/web/flask/app/routes.py", line 21, in index
    posts = current_user.followed_posts().all()
  File "/home/shashi/libs/anaconda3/lib/python2.7/site-packages/werkzeug/local.py", line 348, in __getattr__
    return getattr(self._get_current_object(), name)
AttributeError: 'AnonymousUserMixin' object has no attribute 'followed_posts'
2019-05-09 16:01:08,206 : INFO: Blog Setup [in /home/shashi/Desktop/web/flask/app/__init__.py:47]
2019-05-09 16:01:10,674 : ERROR: Exception on / [GET] [in /home/shashi/libs/anaconda3/lib/python2.7/site-packages/flask/app.py:1761]
Traceback (most recent call last):
  File "/home/shashi/libs/anaconda3/lib/python2.7/site-packages/flask/app.py", line 2292, in wsgi_app
    response = self.full_dispatch_request()
  File "/home/shashi/libs/anaconda3/lib/python2.7/site-packages/flask/app.py", line 1815, in full_dispatch_request
    rv = self.handle_user_exception(e)
  File "/home/shashi/libs/anaconda3/lib/python2.7/site-packages/flask/app.py", line 1718, in handle_user_exception
    reraise(exc_type, exc_value, tb)
  File "/home/shashi/libs/anaconda3/lib/python2.7/site-packages/flask/app.py", line 1813, in full_dispatch_request
    rv = self.dispatch_request()
  File "/home/shashi/libs/anaconda3/lib/python2.7/site-packages/flask/app.py", line 1799, in dispatch_request
    return self.view_functions[rule.endpoint](**req.view_args)
  File "/home/shashi/Desktop/web/flask/app/routes.py", line 21, in index
    posts = current_user.followed_posts().all()
  File "/home/shashi/libs/anaconda3/lib/python2.7/site-packages/werkzeug/local.py", line 348, in __getattr__
    return getattr(self._get_current_object(), name)
AttributeError: 'AnonymousUserMixin' object has no attribute 'followed_posts'
2019-05-09 16:14:10,022 : INFO: Blog Setup [in /home/shashi/Desktop/web/flask/app/__init__.py:47]
2019-05-09 22:56:36,427 : INFO: Blog Setup [in /home/shashi/Desktop/web/flask/app/__init__.py:47]
2019-05-09 22:56:39,584 : ERROR: Exception on /index [GET] [in /home/shashi/libs/anaconda3/lib/python2.7/site-packages/flask/app.py:1761]
Traceback (most recent call last):
  File "/home/shashi/libs/anaconda3/lib/python2.7/site-packages/flask/app.py", line 2292, in wsgi_app
    response = self.full_dispatch_request()
  File "/home/shashi/libs/anaconda3/lib/python2.7/site-packages/flask/app.py", line 1815, in full_dispatch_request
    rv = self.handle_user_exception(e)
  File "/home/shashi/libs/anaconda3/lib/python2.7/site-packages/flask/app.py", line 1718, in handle_user_exception
    reraise(exc_type, exc_value, tb)
  File "/home/shashi/libs/anaconda3/lib/python2.7/site-packages/flask/app.py", line 1813, in full_dispatch_request
    rv = self.dispatch_request()
  File "/home/shashi/libs/anaconda3/lib/python2.7/site-packages/flask/app.py", line 1799, in dispatch_request
    return self.view_functions[rule.endpoint](**req.view_args)
  File "/home/shashi/Desktop/web/flask/app/routes.py", line 24, in index
    page, app.config['POSTS_PER_PAGE'], False)
NameError: global name 'app' is not defined
2019-05-09 22:57:27,052 : INFO: Blog Setup [in /home/shashi/Desktop/web/flask/app/__init__.py:47]
2019-05-09 22:57:28,836 : ERROR: Exception on /index [GET] [in /home/shashi/libs/anaconda3/lib/python2.7/site-packages/flask/app.py:1761]
Traceback (most recent call last):
  File "/home/shashi/libs/anaconda3/lib/python2.7/site-packages/flask/app.py", line 2292, in wsgi_app
    response = self.full_dispatch_request()
  File "/home/shashi/libs/anaconda3/lib/python2.7/site-packages/flask/app.py", line 1815, in full_dispatch_request
    rv = self.handle_user_exception(e)
  File "/home/shashi/libs/anaconda3/lib/python2.7/site-packages/flask/app.py", line 1718, in handle_user_exception
    reraise(exc_type, exc_value, tb)
  File "/home/shashi/libs/anaconda3/lib/python2.7/site-packages/flask/app.py", line 1813, in full_dispatch_request
    rv = self.dispatch_request()
  File "/home/shashi/libs/anaconda3/lib/python2.7/site-packages/flask/app.py", line 1799, in dispatch_request
    return self.view_functions[rule.endpoint](**req.view_args)
  File "/home/shashi/Desktop/web/flask/app/routes.py", line 27, in index
    return render_template('index.html', title = 'Home',form = form, posts=posts.items, next_url=next_url, prev_url=prev_url)
  File "/home/shashi/libs/anaconda3/lib/python2.7/site-packages/flask/templating.py", line 134, in render_template
    return _render(ctx.app.jinja_env.get_or_select_template(template_name_or_list),
  File "/home/shashi/libs/anaconda3/lib/python2.7/site-packages/jinja2/environment.py", line 869, in get_or_select_template
    return self.get_template(template_name_or_list, parent, globals)
  File "/home/shashi/libs/anaconda3/lib/python2.7/site-packages/jinja2/environment.py", line 830, in get_template
    return self._load_template(name, self.make_globals(globals))
  File "/home/shashi/libs/anaconda3/lib/python2.7/site-packages/jinja2/environment.py", line 804, in _load_template
    template = self.loader.load(self, name, globals)
  File "/home/shashi/libs/anaconda3/lib/python2.7/site-packages/jinja2/loaders.py", line 125, in load
    code = environment.compile(source, name, filename)
  File "/home/shashi/libs/anaconda3/lib/python2.7/site-packages/jinja2/environment.py", line 591, in compile
    self.handle_exception(exc_info, source_hint=source_hint)
  File "/home/shashi/libs/anaconda3/lib/python2.7/site-packages/jinja2/environment.py", line 780, in handle_exception
    reraise(exc_type, exc_value, tb)
  File "/home/shashi/Desktop/web/flask/app/templates/index.html", line 26, in template
    {% endblock %}
TemplateSyntaxError: Encountered unknown tag 'endblock'. You probably made a nesting mistake. Jinja is expecting this tag, but currently looking for 'elif' or 'else' or 'endif'. The innermost block that needs to be closed is 'if'.
2019-05-09 22:58:31,472 : INFO: Blog Setup [in /home/shashi/Desktop/web/flask/app/__init__.py:47]
2019-05-09 22:58:31,888 : ERROR: Exception on /index [GET] [in /home/shashi/libs/anaconda3/lib/python2.7/site-packages/flask/app.py:1761]
Traceback (most recent call last):
  File "/home/shashi/libs/anaconda3/lib/python2.7/site-packages/flask/app.py", line 2292, in wsgi_app
    response = self.full_dispatch_request()
  File "/home/shashi/libs/anaconda3/lib/python2.7/site-packages/flask/app.py", line 1815, in full_dispatch_request
    rv = self.handle_user_exception(e)
  File "/home/shashi/libs/anaconda3/lib/python2.7/site-packages/flask/app.py", line 1718, in handle_user_exception
    reraise(exc_type, exc_value, tb)
  File "/home/shashi/libs/anaconda3/lib/python2.7/site-packages/flask/app.py", line 1813, in full_dispatch_request
    rv = self.dispatch_request()
  File "/home/shashi/libs/anaconda3/lib/python2.7/site-packages/flask/app.py", line 1799, in dispatch_request
    return self.view_functions[rule.endpoint](**req.view_args)
  File "/home/shashi/Desktop/web/flask/app/routes.py", line 27, in index
    return render_template('index.html', title = 'Home',form = form, posts=posts.items, next_url=next_url, prev_url=prev_url)
  File "/home/shashi/libs/anaconda3/lib/python2.7/site-packages/flask/templating.py", line 134, in render_template
    return _render(ctx.app.jinja_env.get_or_select_template(template_name_or_list),
  File "/home/shashi/libs/anaconda3/lib/python2.7/site-packages/jinja2/environment.py", line 869, in get_or_select_template
    return self.get_template(template_name_or_list, parent, globals)
  File "/home/shashi/libs/anaconda3/lib/python2.7/site-packages/jinja2/environment.py", line 830, in get_template
    return self._load_template(name, self.make_globals(globals))
  File "/home/shashi/libs/anaconda3/lib/python2.7/site-packages/jinja2/environment.py", line 804, in _load_template
    template = self.loader.load(self, name, globals)
  File "/home/shashi/libs/anaconda3/lib/python2.7/site-packages/jinja2/loaders.py", line 125, in load
    code = environment.compile(source, name, filename)
  File "/home/shashi/libs/anaconda3/lib/python2.7/site-packages/jinja2/environment.py", line 591, in compile
    self.handle_exception(exc_info, source_hint=source_hint)
  File "/home/shashi/libs/anaconda3/lib/python2.7/site-packages/jinja2/environment.py", line 780, in handle_exception
    reraise(exc_type, exc_value, tb)
  File "/home/shashi/Desktop/web/flask/app/templates/index.html", line 26, in template
    {% endblock %}
TemplateSyntaxError: Encountered unknown tag 'endblock'. You probably made a nesting mistake. Jinja is expecting this tag, but currently looking for 'elif' or 'else' or 'endif'. The innermost block that needs to be closed is 'if'.
2019-05-09 22:59:50,160 : INFO: Blog Setup [in /home/shashi/Desktop/web/flask/app/__init__.py:47]
