2019-05-10 16:23:12,840 : ERROR: Exception on /login [GET] [in /home/shashi/libs/anaconda3/lib/python2.7/site-packages/flask/app.py:1761]
Traceback (most recent call last):
  File "/home/shashi/libs/anaconda3/lib/python2.7/site-packages/flask/app.py", line 2292, in wsgi_app
    response = self.full_dispatch_request()
  File "/home/shashi/libs/anaconda3/lib/python2.7/site-packages/flask/app.py", line 1815, in full_dispatch_request
    rv = self.handle_user_exception(e)
  File "/home/shashi/libs/anaconda3/lib/python2.7/site-packages/flask/app.py", line 1718, in handle_user_exception
    reraise(exc_type, exc_value, tb)
  File "/home/shashi/libs/anaconda3/lib/python2.7/site-packages/flask/app.py", line 1813, in full_dispatch_request
    rv = self.dispatch_request()
  File "/home/shashi/libs/anaconda3/lib/python2.7/site-packages/flask/app.py", line 1799, in dispatch_request
    return self.view_functions[rule.endpoint](**req.view_args)
  File "/home/shashi/Desktop/web/flask/app/routes.py", line 55, in login
    return render_template('login.html', title='Sign In', form=form)
  File "/home/shashi/libs/anaconda3/lib/python2.7/site-packages/flask/templating.py", line 135, in render_template
    context, ctx.app)
  File "/home/shashi/libs/anaconda3/lib/python2.7/site-packages/flask/templating.py", line 117, in _render
    rv = template.render(context)
  File "/home/shashi/libs/anaconda3/lib/python2.7/site-packages/jinja2/environment.py", line 1008, in render
    return self.environment.handle_exception(exc_info, True)
  File "/home/shashi/libs/anaconda3/lib/python2.7/site-packages/jinja2/environment.py", line 780, in handle_exception
    reraise(exc_type, exc_value, tb)
  File "/home/shashi/Desktop/web/flask/app/templates/login.html", line 1, in top-level template code
    {% extends "base.html" %}
  File "/home/shashi/Desktop/web/flask/app/templates/base.html", line 25, in top-level template code
    {% block content %}{% endblock %}</html>
  File "/home/shashi/Desktop/web/flask/app/templates/login.html", line 26, in block "content"
    <p>Forgot Your Password<a href="{{ ulr_for('reset_password_request') }}">Click to Reset</a></p>
UndefinedError: 'ulr_for' is undefined
2019-05-10 16:23:15,494 : ERROR: Exception on /login [GET] [in /home/shashi/libs/anaconda3/lib/python2.7/site-packages/flask/app.py:1761]
Traceback (most recent call last):
  File "/home/shashi/libs/anaconda3/lib/python2.7/site-packages/flask/app.py", line 2292, in wsgi_app
    response = self.full_dispatch_request()
  File "/home/shashi/libs/anaconda3/lib/python2.7/site-packages/flask/app.py", line 1815, in full_dispatch_request
    rv = self.handle_user_exception(e)
  File "/home/shashi/libs/anaconda3/lib/python2.7/site-packages/flask/app.py", line 1718, in handle_user_exception
    reraise(exc_type, exc_value, tb)
  File "/home/shashi/libs/anaconda3/lib/python2.7/site-packages/flask/app.py", line 1813, in full_dispatch_request
    rv = self.dispatch_request()
  File "/home/shashi/libs/anaconda3/lib/python2.7/site-packages/flask/app.py", line 1799, in dispatch_request
    return self.view_functions[rule.endpoint](**req.view_args)
  File "/home/shashi/Desktop/web/flask/app/routes.py", line 55, in login
    return render_template('login.html', title='Sign In', form=form)
  File "/home/shashi/libs/anaconda3/lib/python2.7/site-packages/flask/templating.py", line 135, in render_template
    context, ctx.app)
  File "/home/shashi/libs/anaconda3/lib/python2.7/site-packages/flask/templating.py", line 117, in _render
    rv = template.render(context)
  File "/home/shashi/libs/anaconda3/lib/python2.7/site-packages/jinja2/environment.py", line 1008, in render
    return self.environment.handle_exception(exc_info, True)
  File "/home/shashi/libs/anaconda3/lib/python2.7/site-packages/jinja2/environment.py", line 780, in handle_exception
    reraise(exc_type, exc_value, tb)
  File "/home/shashi/Desktop/web/flask/app/templates/login.html", line 1, in top-level template code
    {% extends "base.html" %}
  File "/home/shashi/Desktop/web/flask/app/templates/base.html", line 25, in top-level template code
    {% block content %}{% endblock %}</html>
  File "/home/shashi/Desktop/web/flask/app/templates/login.html", line 26, in block "content"
    <p>Forgot Your Password<a href="{{ ulr_for('reset_password_request') }}">Click to Reset</a></p>
UndefinedError: 'ulr_for' is undefined
2019-05-10 16:23:49,982 : INFO: Blog Setup [in /home/shashi/Desktop/web/flask/app/__init__.py:49]
2019-05-10 16:24:32,470 : ERROR: Exception on /index [GET] [in /home/shashi/libs/anaconda3/lib/python2.7/site-packages/flask/app.py:1761]
Traceback (most recent call last):
  File "/home/shashi/libs/anaconda3/lib/python2.7/site-packages/flask/app.py", line 2292, in wsgi_app
    response = self.full_dispatch_request()
  File "/home/shashi/libs/anaconda3/lib/python2.7/site-packages/flask/app.py", line 1815, in full_dispatch_request
    rv = self.handle_user_exception(e)
  File "/home/shashi/libs/anaconda3/lib/python2.7/site-packages/flask/app.py", line 1718, in handle_user_exception
    reraise(exc_type, exc_value, tb)
  File "/home/shashi/libs/anaconda3/lib/python2.7/site-packages/flask/app.py", line 1813, in full_dispatch_request
    rv = self.dispatch_request()
  File "/home/shashi/libs/anaconda3/lib/python2.7/site-packages/flask/app.py", line 1799, in dispatch_request
    return self.view_functions[rule.endpoint](**req.view_args)
  File "/home/shashi/Desktop/web/flask/app/routes.py", line 24, in index
    posts = current_user.followed_posts().paginate(
  File "/home/shashi/libs/anaconda3/lib/python2.7/site-packages/werkzeug/local.py", line 348, in __getattr__
    return getattr(self._get_current_object(), name)
AttributeError: 'AnonymousUserMixin' object has no attribute 'followed_posts'
2019-05-10 16:25:38,171 : ERROR: Exception on /index [GET] [in /home/shashi/libs/anaconda3/lib/python2.7/site-packages/flask/app.py:1761]
Traceback (most recent call last):
  File "/home/shashi/libs/anaconda3/lib/python2.7/site-packages/flask/app.py", line 2292, in wsgi_app
    response = self.full_dispatch_request()
  File "/home/shashi/libs/anaconda3/lib/python2.7/site-packages/flask/app.py", line 1815, in full_dispatch_request
    rv = self.handle_user_exception(e)
  File "/home/shashi/libs/anaconda3/lib/python2.7/site-packages/flask/app.py", line 1718, in handle_user_exception
    reraise(exc_type, exc_value, tb)
  File "/home/shashi/libs/anaconda3/lib/python2.7/site-packages/flask/app.py", line 1813, in full_dispatch_request
    rv = self.dispatch_request()
  File "/home/shashi/libs/anaconda3/lib/python2.7/site-packages/flask/app.py", line 1799, in dispatch_request
    return self.view_functions[rule.endpoint](**req.view_args)
  File "/home/shashi/Desktop/web/flask/app/routes.py", line 24, in index
    posts = current_user.followed_posts().paginate(
  File "/home/shashi/libs/anaconda3/lib/python2.7/site-packages/werkzeug/local.py", line 348, in __getattr__
    return getattr(self._get_current_object(), name)
AttributeError: 'AnonymousUserMixin' object has no attribute 'followed_posts'
2019-05-10 16:36:19,310 : INFO: Blog Setup [in /home/shashi/Desktop/web/flask/app/__init__.py:49]
2019-05-10 16:36:29,727 : ERROR: Exception on / [GET] [in /home/shashi/libs/anaconda3/lib/python2.7/site-packages/flask/app.py:1761]
Traceback (most recent call last):
  File "/home/shashi/libs/anaconda3/lib/python2.7/site-packages/flask/app.py", line 2292, in wsgi_app
    response = self.full_dispatch_request()
  File "/home/shashi/libs/anaconda3/lib/python2.7/site-packages/flask/app.py", line 1815, in full_dispatch_request
    rv = self.handle_user_exception(e)
  File "/home/shashi/libs/anaconda3/lib/python2.7/site-packages/flask/app.py", line 1718, in handle_user_exception
    reraise(exc_type, exc_value, tb)
  File "/home/shashi/libs/anaconda3/lib/python2.7/site-packages/flask/app.py", line 1813, in full_dispatch_request
    rv = self.dispatch_request()
  File "/home/shashi/libs/anaconda3/lib/python2.7/site-packages/flask/app.py", line 1799, in dispatch_request
    return self.view_functions[rule.endpoint](**req.view_args)
  File "/home/shashi/Desktop/web/flask/app/routes.py", line 24, in index
    posts = current_user.followed_posts().paginate(
  File "/home/shashi/libs/anaconda3/lib/python2.7/site-packages/werkzeug/local.py", line 348, in __getattr__
    return getattr(self._get_current_object(), name)
AttributeError: 'AnonymousUserMixin' object has no attribute 'followed_posts'
2019-05-10 16:36:55,213 : ERROR: Exception on /reset_password_request [POST] [in /home/shashi/libs/anaconda3/lib/python2.7/site-packages/flask/app.py:1761]
Traceback (most recent call last):
  File "/home/shashi/libs/anaconda3/lib/python2.7/site-packages/flask/app.py", line 2292, in wsgi_app
    response = self.full_dispatch_request()
  File "/home/shashi/libs/anaconda3/lib/python2.7/site-packages/flask/app.py", line 1815, in full_dispatch_request
    rv = self.handle_user_exception(e)
  File "/home/shashi/libs/anaconda3/lib/python2.7/site-packages/flask/app.py", line 1718, in handle_user_exception
    reraise(exc_type, exc_value, tb)
  File "/home/shashi/libs/anaconda3/lib/python2.7/site-packages/flask/app.py", line 1813, in full_dispatch_request
    rv = self.dispatch_request()
  File "/home/shashi/libs/anaconda3/lib/python2.7/site-packages/flask/app.py", line 1799, in dispatch_request
    return self.view_functions[rule.endpoint](**req.view_args)
  File "/home/shashi/Desktop/web/flask/app/routes.py", line 146, in reset_password_request
    send_password_reset_mail(user)
NameError: global name 'send_password_reset_mail' is not defined
2019-05-10 16:37:32,363 : INFO: Blog Setup [in /home/shashi/Desktop/web/flask/app/__init__.py:49]
